Workbook

Sheet 1. Desk Study
A2: Data Entry Form for the LIAISON Light touch Reviews - STEP 1: Desk Study
C4: Part A. Empirical indicators for the Desk Study
C5: A.1 | D5: Project identifiers
B6: =IF(NOT(ISBLANK(F6)), CHAR(252), CHAR(251)) -> û | C6: A.1.1 | D6: Project name (if any)
B7: =IF(NOT(ISBLANK(F7)), CHAR(252), CHAR(251)) -> û | C7: A.1.1a | D7: Project website (if available)
B9: =IF(NOT(ISBLANK(F9)), CHAR(252), CHAR(251)) -> û | C9: A.1.2 | D9: Start date (if available & relevant)
B10: =IF(NOT(ISBLANK(F10)), CHAR(252), CHAR(251)) -> û | C10: A.1.3 | D10: End date (if available & relevant)
B11: =IF(NOT(ISBLANK(F11)), CHAR(252), CHAR(251)) -> û | C11: A.1.4 | D11: Current status
B13: =IF(NOT(ISBLANK(F13)), CHAR(252), CHAR(251)) -> û | C13: A.1.5 | D13: Country of residence of coordinator
B15: =IF(NOT(ISBLANK(F15)), CHAR(252), CHAR(251)) -> û | C15: A.1.6 | D15: Region (only if relevant)
B17: =IF(NOT(ISBLANK(F17)), CHAR(252), CHAR(251)) -> û | C17: A.1.7 | D17: Domain
B18: =IF(NOT(ISBLANK(F18)), CHAR(252), CHAR(251)) -> û | C18: A.1.7.a | D18: Type of agriculture/forestry | H18: If other, please specify:
B21: =IF(NOT(ISBLANK(F21)), CHAR(252), CHAR(251)) -> û | C21: A.1.8 | D21: Type of challenges tackled by the project (Please select up to three challenges best describing the project) | E21: 1.
E22: 2.
E23: 3.
B25: =IF(NOT(ISBLANK(F25)), CHAR(252), CHAR(251)) -> û | C25: A.1.9 | D25: Type of solution proposed by the project (Please select the one that closest describes it)
C26: A.1.9.a | D26: Type of innovation supported | H26: If other, please specify:
C30: A.2 | D30: Nature of the project
B31: =IF(NOT(ISBLANK(F31)), CHAR(252), CHAR(251)) -> û | C31: A.2.1 | D31: Geographical coverage: | H31: If multinational, could you indicate the nationalities involved by checking the boxes?
I32: AT | J32: HR | K32: DK | L32: FR | M32: HU | N32: LV | O32: MT | P32: PT | Q32: SI | R32: UK | S32: Other:
I33: BE | J33: CY | K33: EE | L33: DE | M33: IE | N33: LT | O33: NL | P33: RO | Q33: ES | R33: CH
I34: BG | J34: CZ | K34: FI | L34: EL | M34: IT | N34: LU | O34: PL | P34: SK | Q34: SE | R34: NO
B36: =IF(NOT(ISBLANK(F36)), CHAR(252), CHAR(251)) -> û | C36: A.2.2 | D36: Does the project fall under a specific policy framework or programme? | H36: If yes, could you please specify which policy framework or programme?
C40: A.2.3 | D40: Cooperation type (please check the right box) | F40: FORMAL (if there is a signed document) | G40: OR | H40: INFORMAL (all other cases) | O40: In case you would like to clarify your answer, insert your comment here:
B41: =IF(NOT(ISBLANK(F41)), CHAR(252), CHAR(251)) -> û | C41: A.2.3.a | D41: Please specify the type further if possible (only for the one selected)
B43: =IF(NOT(ISBLANK(F43)), CHAR(252), CHAR(251)) -> û | C43: A.2.4 | D43: Please describe how this project or partnership involves multi-actor co-creation of innovation (Max. 100 words)
C46: A.3 | D46: Financing of the project
B47: =IF(NOT(ISBLANK(F47)), CHAR(252), CHAR(251)) -> û | C47: A.3.1 | D47: Type of funding | H47: If public, could you indicate in the dropdownlist the exact source of funding?
B48: =IF(NOT(ISBLANK(F48)), CHAR(252), CHAR(251)) -> û | C48: A.3.1.a | D48: Name of the funding source
D51: Did you have to co-finance (part of) the project? | H51: If yes, how was it co-financed?
B52: =IF(NOT(ISBLANK(F51)), CHAR(252), CHAR(251)) -> û | C52: A.3.2
B54: =IF(NOT(ISBLANK(F54)), CHAR(252), CHAR(251)) -> û | C54: A.3.3 | D54: What is the total value of the project? (in €)
C57: A.4 | D57: Project consortium
B58: =IF(NOT(ISBLANK(F58)),CHAR(252),CHAR(251)) -> û | C58: A.4.1 | D58: How many partner organisations are/were in the consortium?
B59: =IF(NOT(ISBLANK(F59)),CHAR(252),CHAR(251)) -> û | C59: A.4.1.a | D59: How many individual participants are involved?
D62: Which types of organisations are/were involved? (Please tick the applicable boxes) | F62: Individual farmer or forester | G62: Adviser | I62: Processing or marketing SME | K62: Education
F63: Representative/supporting organisation | G63: Researcher | I63: Public body | K63: Other, i.e.:
C64: A.4.2 | F64: Processing or marketing producer organisation | G64: Business | I64: NGO
B66: =IF(NOT(ISBLANK(F66)),CHAR(252),CHAR(251)) -> û | C66: A.4.3 | D66: What type of organisation is the lead partner?
C72: Thank you for your time! The LIAISON team

Sheet 2. Telephone call
A2: Data Entry Form for the LIAISON Light touch Reviews - STEP 2: Telephone call
C4: Part B. Pre-interview factual information
B6: =IF(NOT(ISBLANK(F6)), CHAR(252), CHAR(251)) -> û | C6: B.1 | D6: Name of the LIAISON partner doing the interview
B8: =IF(NOT(ISBLANK(F8)), CHAR(252), CHAR(251)) -> û | C8: B.2 | D8: Organisation of the LIAISON partner
B10: =IF(NOT(ISBLANK(F10)), CHAR(252), CHAR(251)) -> û | C10: B.3 | D10: Date of interview
B12: =IF(NOT(ISBLANK(F12)), CHAR(252), CHAR(251)) -> û | C12: B.4 | D12: Role of the interviewee in the project
B13: =IF(NOT(ISBLANK(F13)), CHAR(252), CHAR(251)) -> û | C13: B.4.1 | D13: Type of organisation
B14: =IF(NOT(ISBLANK(F14)), CHAR(252), CHAR(251)) -> û | C14: B.4.2 | D14: Gender of the interviewee
B16: =IF(NOT(ISBLANK(F16)), CHAR(252), CHAR(251)) -> û | C16: B.5 | D16: Method
B18: =IF(NOT(ISBLANK(F18)), CHAR(252), CHAR(251)) -> û | C18: B.6 | D18: Did you record the interview?
B20: =IF(NOT(ISBLANK(F20)), CHAR(252), CHAR(251)) -> û | C20: B.7 | D20: Did you get an informed consent either orally or in writing?
C23: Part C. Empirical indicators from Telephone call interview
C24: C.1 | D24: Project consortium
B25: =IF(NOT(ISBLANK(F25)), CHAR(252), CHAR(251)) -> û | C25: C.1.1 | D25: How was the project set up? (Max .150 words)
B27: =IF(NOT(ISBLANK(F27)), CHAR(252), CHAR(251)) -> û | C27: C.1.2 | D27: How were partner organisations selected? (Max. 150 words)
B28: =IF(NOT(ISBLANK(F28)), CHAR(252), CHAR(251)) -> û | C28: C.1.2.a | D28: Looking back, do you think that some potentially relevant actors were excluded? | H28: If yes, could you elaborate why you think this is the case? (max. 100 words)
B31: =IF(NOT(ISBLANK(F37)), CHAR(252), CHAR(251)) -> û | C31: C.1.3 | D31: Who took charge of the proposal writing process and why? (if relevant, max. 50 words)
B32: =IF(NOT(ISBLANK(F32)), CHAR(252), CHAR(251)) -> û | C32: C.1.3.a | D32: Was any external help (e.g. an innovation broker) involved in the process? | H32: If yes, could you specify what type of external help? (max. 20 words)
B36: =IF(NOT(ISBLANK(F36)), CHAR(252), CHAR(251)) -> û | C36: C.1.4 | D36: Does your initiative or project have a link to other projects or initiatives? | H36: If yes, could you identify which projects or iniatives and explain the link with your project? (max. 100 words)
C44: C.2 | D44: Project partnership
B45: =IF(NOT(ISBLANK(F45)), CHAR(252), CHAR(251)) -> û | C45: C.2.1 | D45: What were the reasons underpinning the selection of the project coordinator? (Max. 100 words)
B47: =IF(NOT(ISBLANK(F47)), CHAR(252), CHAR(251)) -> û | C47: C.2.2 | D47: Which skills/capacities/knowledge/technologies were the decisive factors in the division of the work? (Max. 200 words)
B49: =IF(NOT(ISBLANK(F49)), CHAR(252), CHAR(251)) -> û | C49: C.2.3 | D49: How was the cooperation and work division between partners formalised? For example, were there contracts, work plans, regulations, codes of conducts, etc.? (Max. 100 words)
B51: =IF(NOT(ISBLANK(F51)), CHAR(252), CHAR(251)) -> û | C51: C.2.4 | D51: How did you work together? Which tools or working methods did you use? (Max. 100 words)
B53: =IF(NOT(ISBLANK(F53)), CHAR(252), CHAR(251)) -> û | C53: C.2.5 | D53: How is/was the gender balance in the project team?
B54: =IF(NOT(ISBLANK(F54)), CHAR(252), CHAR(251)) -> û | C54: C.2.5.a | D54: How does/did this balance affect the project in your opinion? (Max. 50 words)
C56: C.3 | D56: Cooperation during the project
B57: =IF(NOT(ISBLANK(F57)), CHAR(252), CHAR(251)) -> û | C57: C.3.1 | D57: Were some or all partners involved in setting and defining the targets and objectives of the project? | H57: If partners were involved to a great, some or a small extent, How was their involvement organised? (Max. 100 words)
B62: =IF(NOT(ISBLANK(F62)), CHAR(252), CHAR(251)) -> û | C62: C.3.2 | D62: Which mechanisms are/were in place to stimulate knowledge and information exchange between the organisations involved? (Max. 200 words)
B63: =IF(NOT(ISBLANK(F63)), CHAR(252), CHAR(251)) -> û | C63: C.3.2.a | D63: How effective are/were the applied mechanisms, in your opinion?
B65: =IF(NOT(ISBLANK(F65)), CHAR(252), CHAR(251)) -> û | C65: C.3.3 | D65: Overall, how would you evaluate the cooperation between the partners & why? (Max. 100 words)
C68: C.4 | D68: Project performance
B69: =IF(NOT(ISBLANK(F69)), CHAR(252), CHAR(251)) -> û | C69: C.4.1 | D69: What kind of information or assistance and from whom will/did you need to bring your project to a successful end? (Max. 100 words)
B70: =IF(NOT(ISBLANK(F70)), CHAR(252), CHAR(251)) -> û | C70: C.4.1.a | D70: Was the right information available?
B71: =IF(NOT(ISBLANK(F71)), CHAR(252), CHAR(251)) -> û | C71: C.4.1.b | D71: Did you have access to the right information?
B72: =IF(NOT(ISBLANK(F72)), CHAR(252), CHAR(251)) -> û | C72: C.4.1.c | D72: Any other comment you would like to add on information? (if relevant)
B74: =IF(NOT(ISBLANK(F74)), CHAR(252), CHAR(251)) -> û | C74: C.4.2 | D74: To what extent is/was communication about the project/initiative outside the involved organisations of importance? | H74: If important to a great, some or a small extent, could you please explain your answer? (Max. 50 words)
B78: =IF(NOT(ISBLANK(F78)), CHAR(252), CHAR(251)) -> û | C78: C.4.3 | D78: How and on which parameters do/did you monitor the performance of the project ? (max. 100 words)
C81: C.5 | D81: Project outcomes
C82: C.5.1 | D82: On a scale from 0 to 10, how do you evaluate the (potential) success of your project on the following topics: (Please select the correct number from the drop down menu) | G82: Scale: | H82: 0 | I82: 1 | J82: 2 | K82: 3 | L82: 4 | M82: 5 | N82: 6 | O82: 7 | P82: 8 | Q82: 9 | R82: 10
...

Sheet 3. After the interview
A2: Data Entry Form for the LIAISON Light touch Reviews - STEP 3: After the interview
C4: Part D. Further conceptual understanding about the project
B5: =IF(NOT(ISBLANK(F5)), CHAR(252), CHAR(251)) -> û | C5: D.1 | D5: In your interpretation, how would you assess the level of co-creation within the project? | H5: Could you shortly motivate your answer? (Max. 100 words)
B8: =IF(NOT(ISBLANK(F8)), CHAR(252), CHAR(251)) -> û | C8: D.2 | D8: Based on the listed activities, where would you locate the project in the innovation spiral?
C10: D.3 | D10: Which of the four pathways is supported by these activities in the project? Please tick the right box, multiple selections are possible | F10: Pathway 1 - Capturing, articulating and nurturing 'New Ideas' | G10: Pathway 3 - Dissemination and the embedding of effective innovations
F11: Pathway 2 - Building the capacity of innovation actors | G11: Pathway 4 - Improving the 'Enabling Environment' for innovation
B14: =IF(NOT(ISBLANK(F14)), CHAR(252), CHAR(251)) -> û | C14: D.4 | D14: In your interpretation, how is the organisational nature of this project? (Max. 100 words)
B16: =IF(NOT(ISBLANK(F18)), CHAR(252), CHAR(251)) -> û | C16: D.5 | D16: What is your main impression of this case: Which are the three key elements that we should take along in further analysis? | E16: 1.
E17: 2.
E18: 3.
C26: Thank you for your time! The LIAISON team

Sheet Compiled format
A1: # | B1: Step 1. Desk study | AV1: Step 2. Telephone call | CU1: Step 3. After the interview
B2: Project identifiers | R2: Nature of the project | AC2: Project financing | AI2: Project consortium | AV2: Pre-interview factual information | BE2: Project consortium | BN2: Project partnership | BT2: Cooperation during the project | BY2: Project performance | CF2: Project outcomes | CM2: Evaluation of the project | CU2: Further conceptual understanding about the project
B3: Project name | C3: Project website | D3: Start date | E3: End date | F3: Current status | G3: Country of residence of coordinator | H3: Region | I3: Domain | J3: Type of agriculture/forestry | K3: If other, please specify: | L3: Type of challenges tackled by the project 1 | M3: Type of challenges tackled by the project 2 | N3: Type of challenges tackled by the project 3 | O3: Type of solution proposed by the project | P3: Type of innovation supported | Q3: If other type of innovation: specify | R3: Geographical coverage | S3: If multinational: No. Of countries covered | T3: If other country: specify | U3: Does the project fall under a specific policy framework or programme? | V3: Policy framework or programme | W3: Formal cooperation type | X3: Formal types explained | Y3: Informal Cooperation type | Z3: Informal types explained | AA3: Additional comment | AB3: Please describe how this project or partnership involves multi-actor co-creation of innovation | AC3: Type of funding | AD3: If public: Type of public funding | AE3: Name of the funding source | AF3: Did you have to co-finance (part of) the project? | AG3: If co-financed: | AH3: What is the total value of the project? (in €) | AI3: How many partner organisations are/were in the consortium? | AJ3: Individual farmer or forester | AK3: Representative/supporting organisation | AL3: Processing or marketing producer organisation | AM3: Adviser | AN3: Researcher | AO3: Business | AP3: Processing or marketing SME | AQ3: Public body | AR3: NGO | AS3: Education | AT3: Other (specific) | AU3: What type of organisation is the lead partner? | AV3: Name of the LIAISON partner doing the interview | AW3: Organisation of the LIAISON partner | AX3: Date of interview | AY3: Role of the interviewee in the project | AZ3: Type of organisation | BA3: Gender of the interviewee | BB3: Method | BC3: Did you record the interview? | BD3: Did you get an informed consent either orally or in writing? | BE3: How was the project set up? | BF3: How were partner organisations selected? | BG3: Looking back, do you think that some potentially relevant actors were excluded? | BH3: If yes, could you elaborate why you think this is the case? | BI3: Who took charge of the proposal writing process and why? (if relevant) | BJ3: Was any external help (e.g. an innovation broker) involved in the process? | BK3: If yes, could you specify what type of external help? | BL3: Does your initiative or project have a link to other projects or initiatives? | BM3: If yes, could you identify which projects or iniatives and explain the link with your project? | BN3: What were the reasons underpinning the selection of the project coordinator? | BO3: Which skills/capacities/knowledge/technologies were the decisive factors in the division of the work? | BP3: How was the cooperation and work division between partners formalised? For example, were there contracts, work plans, regulations, codes of conducts, etc.? | BQ3: How did you work together? Which tools or working methods did you use? | BR3: How is/was the gender balance in the project team? | BS3: How does/did this balance affect the project in your opinion? | BT3: Were some or all partners involved in setting and defining the targets and objectives of the project? | BU3: If partners were involved to a great, some or a small extent, How was their involvement organised? | BV3: Which mechanisms are/were in place to stimulate knowledge and information exchange between the organisations involved? | BW3: How effective are/were the applied mechanisms, in your opinion? | BX3: Overall, how would you evaluate the cooperation between the partners & why? | BY3: What kind of information and from whom will/did you need to bring your project to a successful end? | BZ3: Was the right information available? | CA3: Did you have access to the right information? | CB3: Any other comment you would like to add on information? (if relevant) | CC3: To what extent is/was communication about the project/initiative outside the involved organisations of importance? | CD3: If important to a great, some or a small extent, could you please explain your answer? | CE3: How do/did you monitor the performance of the project and on which parameters? | CF3: Potential project success on: Innovation | CG3: Potential project success on: Research (acquiring new knowledge) | CH3: Potential project success on: Communication or outreach on the project | CI3: Potential project success on: Initial ideas compared to what has been implemented during the project/initiative | CJ3: Would you like to give any additional comments on this scoring? | CK3: How is/was the success of the project measured by any external funder(s)? | CL3: How do you evaluate the role of the policy environment in the success of your project? | CM3: Succes factor 1 | CN3: Succes factor 2 | CO3: Succes factor 3 | CP3: Why? | CQ3: What is/was the most significant bottleneck or challenge during the project? | CR3: How is/was it addressed? | CS3: What are the main lessons you take home from this experience (so far)? | CT3: What kind of follow up or next steps are planned after the finalisation of the project? | CU3: In your interpretation, how would you assess the level of co-creation within the project? | CV3: Could you shortly motivate your answer? | CW3: Based on the listed activities, where would you locate the project in the innovation spiral? | CX3: Pathway 1 | CY3: Pathway 2 | CZ3: Pathway 3 | DA3: Pathway 4 | DB3: In your interpretation, how is the organisational nature of this project? | DC3: Element 1 for further analysis | DD3: Element 2 for further analysis | DE3: Element 3 for further analysis
B4: ='1. Desk Study'!$F$6 -> 0 | C4: ='1. Desk Study'!$F$7 -> 0 | D4: ='1. Desk Study'!$F$9 -> 0 | E4: ='1. Desk Study'!$F$10 -> 0 | F4: ='1. Desk Study'!$F$11 -> 0 | G4: ='1. Desk Study'!$F$13 -> 0 | H4: ='1. Desk Study'!$F$15 -> 0 | I4: ='1. Desk Study'!$F$17 -> 0 | J4: ='1. Desk Study'!$F$18 -> 0 | K4: ='1. Desk Study'!$I$19 -> 0 | L4: ='1. Desk Study'!$F$21 -> 0 | M4: ='1. Desk Study'!$F$22 -> 0 | N4: ='1. Desk Study'!$F$23 -> 0 | O4: ='1. Desk Study'!$F$25 -> 0 | P4: ='1. Desk Study'!$F$26 -> 0 | Q4: ='1. Desk Study'!$I$27 -> 0 | R4: ='1. Desk Study'!$F$31 -> 0 | S4: ='Results for involved countries'!$B$33 -> 0 | T4: ='1. Desk Study'!$T$32 -> 0 | U4: ='1. Desk Study'!$F$36 -> 0 | V4: ='1. Desk Study'!$I$37 -> 0 | W4: FALSE | X4: ='1. Desk Study'!$F$41 -> 0 | Y4: FALSE | Z4: ='1. Desk Study'!$H$41 -> 0 | AA4: ='1. Desk Study'!$P$41 -> 0 | AB4: ='1. Desk Study'!$F$43 -> 0 | AC4: ='1. Desk Study'!$F$47 -> 0 | AD4: ='1. Desk Study'!$I$48 -> 0 | AE4: ='1. Desk Study'!$F$48 -> 0 | AF4: ='1. Desk Study'!$F$51 -> 0 | AG4: ='1. Desk Study'!$I$52 -> 0 | AH4: ='1. Desk Study'!$F$54 -> 0 | AI4: ='1. Desk Study'!$F$58 -> 0 | AJ4: FALSE | AK4: FALSE | AL4: FALSE | AM4: FALSE | AN4: FALSE | AO4: FALSE | AP4: FALSE | AQ4: FALSE | AR4: FALSE | AS4: FALSE | AT4: ='1. Desk Study'!$L$63 -> 0 | AU4: ='1. Desk Study'!$F$66 -> 0 | AV4: ='2. Telephone call'!$F$6 -> 0 | AW4: ='2. Telephone call'!$F$8 -> 0 | AX4: ='2. Telephone call'!$F$10 -> 0 | AY4: ='2. Telephone call'!$F$12 -> 0 | AZ4: ='2. Telephone call'!$F$13 -> 0 | BA4: ='2. Telephone call'!$F$14 -> 0 | BB4: ='2. Telephone call'!$F$16 -> 0 | BC4: ='2. Telephone call'!$F$18 -> 0 | BD4: ='2. Telephone call'!$F$20 -> 0 | BE4: ='2. Telephone call'!$F$25 -> 0 | BF4: ='2. Telephone call'!$F$27 -> 0 | BG4: ='2. Telephone call'!$F$28 -> 0 | BH4: ='2. Telephone call'!$I$29 -> 0 | BI4: ='2. Telephone call'!$F$31 -> 0 | BJ4: ='2. Telephone call'!$F$32 -> 0 | BK4: ='2. Telephone call'!$I$33 -> 0 | BL4: ='2. Telephone call'!$F$36 -> 0 | BM4: ='2. Telephone call'!$I$37 -> 0 | BN4: ='2. Telephone call'!$F$45 -> 0 | BO4: ='2. Telephone call'!$F$47 -> 0 | BP4: ='2. Telephone call'!$F$49 -> 0 | BQ4: ='2. Telephone call'!$F$51 -> 0 | BR4: ='2. Telephone call'!$F$53 -> 0 | BS4: ='2. Telephone call'!$F$54 -> 0 | BT4: ='2. Telephone call'!$F$57 -> 0 | BU4: ='2. Telephone call'!$I$58 -> 0 | BV4: ='2. Telephone call'!$F$62 -> 0 | BW4: ='2. Telephone call'!$F$63 -> 0 | BX4: ='2. Telephone call'!$F$65 -> 0 | BY4: ='2. Telephone call'!$F$69 -> 0 | BZ4: ='2. Telephone call'!$F$70 -> 0 | CA4: ='2. Telephone call'!$F$71 -> 0 | CB4: ='2. Telephone call'!$F$72 -> 0 | CC4: ='2. Telephone call'!$F$74 -> 0 | CD4: ='2. Telephone call'!$I$75 -> 0 | CE4: ='2. Telephone call'!$F$78 -> 0 | CF4: ='2. Telephone call'!$F$84 -> 0 | CG4: ='2. Telephone call'!$F$85 -> 0 | CH4: ='2. Telephone call'!$F$86 -> 0 | CI4: ='2. Telephone call'!$F$87 -> 0 | CJ4: ='2. Telephone call'!$F$88 -> 0 | CK4: ='2. Telephone call'!$F$90 -> 0 | CL4: ='2. Telephone call'!$F$92 -> 0 | CM4: ='2. Telephone call'!$F$95 -> 0 | CN4: ='2. Telephone call'!$F$96 -> 0 | CO4: ='2. Telephone call'!$F$97 -> 0 | CP4: ='2. Telephone call'!$F$98 -> 0 | CQ4: ='2. Telephone call'!$F$100 -> 0 | CR4: ='2. Telephone call'!$F$101 -> 0 | CS4: ='2. Telephone call'!$F$103 -> 0 | CT4: ='2. Telephone call'!$F$105 -> 0 | CU4: ='3. After the interview'!$F$5 -> 0 | CV4: ='3. After the interview'!$I$6 -> 0 | CW4: ='3. After the interview'!$F$8 -> 0 | CX4: FALSE | CY4: FALSE | CZ4: FALSE | DA4: FALSE | DB4: ='3. After the interview'!$F$14 -> 0 | DC4: ='3. After the interview'!$F$16 -> 0 | DD4: ='3. After the interview'!$F$17 -> 0 | DE4: ='3. After the interview'!$F$18 -> 0

Sheet Practical
A1: Project Name | B1: Would you be interested/willing in becoming a LIAISON case study? | C1: Can we refer to the project by name? | D1: Would you like to be updated on the progress of the LIAISON project? (Newsletter, events, etc.) | E1: Informed consent ok?
A2: ='1. Desk Study'!F6 -> 0 | B2: ='2. Telephone call'!F110 -> 0 | C2: ='2. Telephone call'!F111 -> 0 | D2: ='2. Telephone call'!F112 -> 0 | E2: ='2. Telephone call'!F20 -> 0

Sheet Results for involved countries
A1: MS | B1: Cell link for question on nationalities involved
A2: AT | B2: FALSE
A3: BE | B3: FALSE
A4: BG | B4: FALSE
A5: HR | B5: FALSE
A6: CY | B6: FALSE
A7: CZ | B7: FALSE
A8: DK | B8: FALSE
A9: EE | B9: FALSE
A10: FI | B10: FALSE
A11: FR | B11: FALSE
A12: DE | B12: FALSE
A13: EL | B13: FALSE
... A32: Other | B32: FALSE
A33: Total | B33: =COUNTIF(B2:B32, TRUE) -> 0

Sheet Lists
B4: Status of project | G4: Nationalities | I4: Yes/No answers | M4: Type of interview | P4: Informed consent
B5: planned or just started | G5: AT | I5: Yes | M5: Telephone | P5: Yes, I got an oral agreement
B6: on-going with no outcomes available | G6: BE | I6: No | M6: Skype | P6: Yes, I have a signed agreement which I stored in a secure place
B7: on-going with some outcomes available | G7: BG | I7: Not relevant | M7: Face-to-face | P7: No
B8: finished with no proven effects | G8: HR | M8: Other
B9: finished with proven effects | G9: CY
B10: not sure | G10: CZ
G11: DK | I11: Formal cooperation type | M11: Lead partner type
B12: Domains | G12: EE | I12: recognised legal entity | M12: Individual farmer or forester
B13: agriculture | G13: FI | I13: formal network | M13: Representative/supporting organisation
B14: forestry | G14: FR | I14: project consortium | M14: Processing or marketing producer organisation
B15: rural development | G15: DE | I15: cooperative | M15: Adviser
G16: EL | I16: other | M16: Researcher
B17: Gender | G17: HU | M17: Business
B18: Female | G18: IE | I18: Informal cooperation type | M18: Processing or marketing SME
B19: Male | G19: IT | I19: informal network | M19: Public body
B20: Other | G20: LV | I20: voluntary cooperation | M20: NGO
G21: LT | I21: other | M21: Education
B22: Geographical coverage | G22: LU | M22: Other
B23: Local | G23: MT
B24: Regional | G24: NL | I24: Funding | M24: Type of challenge
B25: National | G25: PL | I25: Public | M25: Resource management - Water
B26: Multinational | G26: PT | I26: Public-private | M26: Resource management - Energy
G27: RO | I27: Private | M27: Resource management - Waste/side stream valorisation
B28: Gender balance | G28: SK | I28: No funding/alternative type of funding | M28: Resource management - Soil
B29: More men than women | G29: SI | M29: Resource management - Nutrients
B30: More women than men | G30: ES | I30: Funding source | M30: Food safety/product quality - Food safety
B31: More or less equal | G31: SE | I31: National research funds | M31: Food safety/product quality - Nutritional value
G32: UK | I32: National RDP funding | M32: Food safety/product quality - Product quality
B33: Innovation spiral | G33: CH | I33: International funding (non-EU) | M33: Pollution - Water pollution
B34: Initial idea | G34: NO | I34: EU project funding | M34: Pollution - Soil pollution
B35: Inspiration phase | G35: Other | I35: Not applicable | M35: Pollution - Air quality
B36: Planning phase | M36: Pollution - Emissions control (chemicals)
B37: Development phase | M37: Socio-economic sustainability/competitiveness - labour management
B38: Realisation phase | M38: Socio-economic sustainability/competitiveness - occupational safety
B39: Dissemination phase | M39: Socio-economic sustainability/competitiveness - cost reduction
B40: Embedding phase | M40: Socio-economic sustainability/competitiveness - benchmarking
B41: Not sure | M41: Socio-economic sustainability/competitiveness - ergonomics
M42: Socio-economic sustainability/competitiveness - Intergenerational renewal
B43: Pathways for innovation support | I43: Innovation types | M43: Biodiversity/nature/landscape management
...
